Workbook
Name ______DAT1: [1]CI!#REF!
Name ______DAT1: [1]CI!#REF!
Name ______DAT5: [1]CI!#REF!
Name ______DAT5: [1]CI!#REF!
Name ______f100: '[2]EE-SIMC'!#REF!
Name ______f100: '[2]EE-SIMC'!#REF!
Name _____DAT10: #REF!
Name _____DAT10: #REF!
Name _____DAT11: #REF!
Name _____DAT11: #REF!
Name _____DAT12: #REF!
Name _____DAT12: #REF!
Name _____DAT13: #REF!
Name _____DAT13: #REF!
Name _____DAT14: #REF!
Name _____DAT14: #REF!
Name _____DAT15: #REF!
Name _____DAT15: #REF!
Name _____DAT16: #REF!
Name _____DAT16: #REF!
Name _____DAT17: #REF!
Name _____DAT17: #REF!
Name _____DAT18: #REF!
Name _____DAT18: #REF!
Name _____DAT19: #REF!
Name _____DAT19: #REF!
Name _____DAT2: #REF!
Name _____DAT2: #REF!
Name _____DAT20: #REF!
Name _____DAT20: #REF!
Name _____DAT21: #REF!
Name _____DAT21: #REF!
Name _____DAT3: #REF!
Name _____DAT3: #REF!
Name _____DAT4: #REF!
Name _____DAT4: #REF!
Name _____DAT6: #REF!
Name _____DAT6: #REF!
Name _____DAT7: #REF!
Name _____DAT7: #REF!
Name _____DAT8: #REF!
Name _____DAT8: #REF!
Name _____DAT9: #REF!
Name _____DAT9: #REF!
Name _____FAC1: [3]สรุป!$C$307
Name ____DAT1: [1]CI!#REF!
Name ____DAT1: [1]CI!#REF!
Name ____DAT10: #REF!
Name ____DAT10: #REF!
Name ____DAT11: #REF!
Name ____DAT11: #REF!
Name ____DAT12: #REF!
Name ____DAT12: #REF!
Name ____DAT13: #REF!
Name ____DAT13: #REF!
Name ____DAT14: #REF!
Name ____DAT14: #REF!
Name ____DAT15: #REF!
Name ____DAT15: #REF!
Name ____DAT16: #REF!

Sheet NKC2
A1: Master Schedule อาคาร Ratchadamnoen Center 2
A2: Project : ก่อสร้างอาคารศูนย์การเรียนรู้แห่งชาติ OKMD : OKMD National Knowledge Center | F2: =TRANSPOSE('NKC2'!J129:CM129) -> #VALUE!
A3: Owner : สำนักงานบริหารและพัฒนาองค์ความรู้ (องค์การมหาชน) | J3: MB | CA3: Contract Duration : 840 Days
A4: Consult : บริษัท พี.พี.เอส.เอ็น จำกัด | CA4: Start Date : | CJ4: 45901
A5: Contractor : บริษัท เพาเวอร์ไลน์ เอ็นจิเนียริ่ง จำกัด (มหาชน) | CA5: Finish Date : | CJ5: =CJ4+840-1 -> 46740
A8: Item | C8: Description | E8: Contract Include Vat | G8: Plan/ Actual | BE8: 2027
H9: % | J9: M6 | N9: M7 | R9: M8 | V9: M9 | AA9: M10 | AE9: M11 | AJ9: M12 | AN9: M13 | AR9: M14 | AW9: M15 | BA9: M16 | BE9: M17 | BJ9: M18 | BN9: M19 | BR9: M20 | BW9: M21 | CA9: M22 | CE9: M23 | CJ9: M24 | CN9: M25 | CR9: M26 | CV9: M27 | CZ9: M28
J10: 46054 | N10: 46082 | R10: 46113 | V10: 46143 | AA10: 46174 | AE10: 46204 | AJ10: 46235 | AN10: 46266 | AR10: 46296 | AW10: 46327 | BA10: 46357 | BE10: 46388 | BJ10: 46419 | BN10: 46447 | BR10: 46478 | BW10: 46508 | CA10: 46539 | CE10: 46569 | CJ10: 46600 | CN10: 46631 | CR10: 46661 | CV10: 46692 | CZ10: 46722
B11: WBS | D11: Activities | F11: Amount | G11: P/A | H11: % | I11: Amount from progress | J11: 46059 | K11: =J11+7 -> 46066 | L11: =K11+7 -> 46073 | M11: =L11+7 -> 46080 | N11: =M11+7 -> 46087 | O11: =N11+7 -> 46094 | P11: =O11+7 -> 46101 | Q11: =P11+7 -> 46108 | R11: =Q11+7 -> 46115 | ... CM11: =CL11+7 -> 46626 | CN11: =CL11+7 -> 46626 | CO11: =CN11+7 -> 46633 | CP11: =CO11+7 -> 46640 | CQ11: =CP11+7 -> 46647 | CR11: =CQ11+7 -> 46654 | CS11: =CR11+7 -> 46661 | CT11: =CS11+7 -> 46668 | CU11: =CT11+7 -> 46675 | CV11: =CU11+7 -> 46682 | ... CZ11: =CY11+7 -> 46710
C12: โครงการจัดตั้งศูนย์การเรียนรู้แห่งชาติ OKMD : OKMD National Knowledge Center | E12: 750000000 | F12: =E12 -> 750000000 | G12: P | H12: =SUM(J12:CZ12) -> 0
F13: =E12 -> 750000000 | G13: A | H13: =SUM(J13:CZ13) -> 0
A14: 1 | B14: =A14 -> 1 | C14: งานก่อสร้างอาคาร Ratchadamnoen Center 2 | D14: =C14 -> งานก่อสร้างอาคาร Ratchadamnoen Center 2 | E14: =E16+E18+E48+E58+E80+E82+E104+E112+E126 -> 1.4128269e+08 | F14: =E14 -> 1.4128269e+08 | G14: P | H14: =SUM(J14:CZ14) -> 0 | I14: =I16+I18+I48+I58+I80+I82+I104+I112+I126 -> 1.4126263e+08
B15: =B14 -> 1 | D15: =D14 -> งานก่อสร้างอาคาร Ratchadamnoen Center 2 | F15: =E14 -> 1.4128269e+08 | G15: A | H15: =SUM(J15:CZ15) -> 0 | I15: =I17+I19+I49+I59+I81+I83+I105+I113+I127 -> 272275.05
A16: 1.1 | B16: =A16 -> 1.1 | C16: งานรื้อถอนโครงสร้างและสถาปัตยกรรมอาคารเดิม | D16: =C16 -> งานรื้อถอนโครงสร้างและสถาปัตยกรรมอาคารเดิม | E16: 358256.64 | F16: =E16 -> 358256.64 | G16: P | H16: =SUM(J16:CZ16) -> 1 | I16: =H16*F16 -> 358256.64 | N16: 0.05 | O16: 0.07 | P16: 0.07 | Q16: 0.08 | R16: 0.1 | S16: 0.1 | T16: 0.15 | U16: 0.1 | V16: 0.08 | W16: 0.08 | X16: 0.03 | Y16: 0.03 | Z16: 0.03 | AA16: 0.03
B17: =B16 -> 1.1 | D17: =D16 -> งานรื้อถอนโครงสร้างและสถาปัตยกรรมอาคารเดิม | F17: =E16 -> 358256.64 | G17: A | H17: =SUM(J17:CZ17) -> 0.76 | I17: =H17*F17 -> 272275.05 | R17: 0.02 | S17: 0.05 | T17: 0.05 | U17: 0.08 | V17: 0.08 | W17: 0.05 | X17: 0.05 | Y17: 0.05 | Z17: 0.05 | AA17: 0.08 | AB17: 0.08 | AC17: 0.08 | AD17: 0.04
A18: 1.2 | B18: =A18 -> 1.2 | C18: งานโครงสร้าง | D18: =C18 -> งานโครงสร้าง | E18: =SUM(E20:E47) -> 15467541 | F18: =E18 -> 15467541 | G18: P | H18: =SUM(J18:CZ18) -> 0 | I18: =I20+I22+I24+I26+I28+I30+I32+I34+I36+I38+I40+I42+I46 -> 15467541
B19: =B18 -> 1.2 | D19: =D18 -> งานโครงสร้าง | F19: =E18 -> 15467541 | G19: A | H19: =SUM(J19:CZ19) -> 0 | I19: =I21+I23+I25+I27+I29+I31+I33+I35+I37+I39+I41+I43+I47 -> 0 | CN19: =SUMPRODUCT(($G$20:$G$47="A")*$F$20:$F$47*CN20:CN47)/$F$18 -> 0 | CO19: =SUMPRODUCT(($G$20:$G$47="A")*$F$20:$F$47*CO20:CO47)/$F$18 -> 0 | CP19: =SUMPRODUCT(($G$20:$G$47="A")*$F$20:$F$47*CP20:CP47)/$F$18 -> 0 | CQ19: =SUMPRODUCT(($G$20:$G$47="A")*$F$20:$F$47*CQ20:CQ47)/$F$18 -> 0 | CR19: =SUMPRODUCT(($G$20:$G$47="A")*$F$20:$F$47*CR20:CR47)/$F$18 -> 0 | CS19: =SUMPRODUCT(($G$20:$G$47="A")*$F$20:$F$47*CS20:CS47)/$F$18 -> 0 | CT19: =SUMPRODUCT(($G$20:$G$47="A")*$F$20:$F$47*CT20:CT47)/$F$18 -> 0 | CU19: =SUMPRODUCT(($G$20:$G$47="A")*$F$20:$F$47*CU20:CU47)/$F$18 -> 0 | ... CY19: =SUMPRODUCT(($G$20:$G$47="A")*$F$20:$F$47*CY20:CY47)/$F$18 -> 0
A20: 1.2.1 | B20: =A20 -> 1.2.1 | C20: งานโครงสร้างลิฟต์ | D20: =C20 -> งานโครงสร้างลิฟต์ | E20: 1038486.6 | F20: =E20 -> 1038486.6 | G20: P | H20: =SUM(J20:CZ20) -> 1 | I20: =H20*F20 -> 1038486.6 | R20: 0.02 | S20: 0.02 | T20: 0.04 | U20: 0.04 | V20: 0.09 | W20: 0.1 | X20: 0.1 | Y20: 0.1 | Z20: 0.1 | AA20: 0.1 | AB20: 0.1 | AC20: 0.1 | AD20: 0.05 | AE20: 0.04 | AF20: 0
B21: =B20 -> 1.2.1 | D21: =D20 -> งานโครงสร้างลิฟต์ | F21: =E20 -> 1038486.6 | G21: A | H21: =SUM(J21:CZ21) -> 0 | I21: =H21*F21 -> 0
A22: 1.2.2 | B22: =A22 -> 1.2.2 | C22: งานโครงชั้นหลังคา (FL. +18.95 m. ) | D22: =C22 -> งานโครงชั้นหลังคา (FL. +18.95 m. ) | E22: 4195354.6 | F22: =E22 -> 4195354.6 | G22: P | H22: =SUM(J22:CZ22) -> 1 | I22: =H22*F22 -> 4195354.6 | R22: 0.1 | S22: 0.21 | T22: 0.25 | U22: 0.22 | V22: 0.1 | W22: 0.05 | X22: 0.03 | Y22: 0.02 | Z22: 0.02
B23: =B22 -> 1.2.2 | D23: =D22 -> งานโครงชั้นหลังคา (FL. +18.95 m. ) | F23: =E22 -> 4195354.6 | G23: A | H23: =SUM(J23:CZ23) -> 0 | I23: =H23*F23 -> 0
A24: 1.2.3 | B24: =A24 -> 1.2.3 | C24: งานโครงหลังคาห้องสนามหลวง ห้องศาสนา | D24: =C24 -> งานโครงหลังคาห้องสนามหลวง ห้องศาสนา | E24: 1034941.9 | F24: =E24 -> 1034941.9 | G24: P | H24: =SUM(J24:CZ24) -> 1 | I24: =H24*F24 -> 1034941.9 | V24: 0.1 | W24: 0.21 | X24: 0.25 | Y24: 0.15 | Z24: 0.1 | AA24: 0.1 | AB24: 0.09
B25: =B24 -> 1.2.3 | D25: =D24 -> งานโครงหลังคาห้องสนามหลวง ห้องศาสนา | F25: =E24 -> 1034941.9 | G25: A | H25: =SUM(J25:CZ25) -> 0 | I25: =H25*F25 -> 0
A26: 1.2.4 | B26: =A26 -> 1.2.4 | C26: งานซ่อมแซมโครงสร้างอาคารเดิม | D26: =C26 -> งานซ่อมแซมโครงสร้างอาคารเดิม | E26: 881401.59 | F26: =E26 -> 881401.59 | G26: P | H26: =SUM(J26:CZ26) -> 1 | I26: =H26*F26 -> 881401.59 | Y26: 0.05 | Z26: 0.05 | AA26: 0.1 | AB26: 0.1 | AC26: 0.15 | AD26: 0.15 | AE26: 0.15 | AF26: 0.1 | AG26: 0.1 | AH26: 0.05
B27: =B26 -> 1.2.4 | D27: =D26 -> งานซ่อมแซมโครงสร้างอาคารเดิม | F27: =E26 -> 881401.59 | G27: A | H27: =SUM(J27:CZ27) -> 0 | I27: =H27*F27 -> 0
A28: 1.2.5 | B28: =A28 -> 1.2.5 | C28: ห้องน้ำและห้องเตรียมอาหาร | D28: =C28 -> ห้องน้ำและห้องเตรียมอาหาร | E28: 3388363.7 | F28: =E28 -> 3388363.7 | G28: P | H28: =SUM(J28:CZ28) -> 1 | I28: =H28*F28 -> 3388363.7 | U28: 0.05 | V28: 0.1 | W28: 0.1 | X28: 0.1 | Y28: 0.1 | Z28: 0.1 | AA28: 0.1 | AB28: 0.1 | AC28: 0.1 | AD28: 0.1 | AE28: 0.05
B29: =B28 -> 1.2.5 | D29: =D28 -> ห้องน้ำและห้องเตรียมอาหาร | F29: =E28 -> 3388363.7 | G29: A | H29: =SUM(J29:CZ29) -> 0 | I29: =H29*F29 -> 0
A30: 1.2.6 | B30: =A30 -> 1.2.6 | C30: งานโครงสร้างชั้นลอย | D30: =C30 -> งานโครงสร้างชั้นลอย | E30: 3778708 | F30: =E30 -> 3778708 | G30: P | H30: =SUM(J30:CZ30) -> 1 | I30: =H30*F30 -> 3778708 | V30: 0.08 | W30: 0.1 | X30: 0.1 | Y30: 0.1 | Z30: 0.15 | AA30: 0.2 | AB30: 0.1 | AC30: 0.1 | AD30: 0.07
B31: =B30 -> 1.2.6 | D31: =D30 -> งานโครงสร้างชั้นลอย | F31: =E30 -> 3778708 | G31: A | H31: =SUM(J31:CZ31) -> 0 | I31: =H31*F31 -> 0
A32: 1.2.7 | B32: =A32 -> 1.2.7 | C32: งานโครงสร้างต่อเติมพื้นชั้น 2 Area = 59.06 sq.m. ( GL.1-5/B-C & GL.33-37/B-C ) | D32: =C32 -> งานโครงสร้างต่อเติมพื้นชั้น 2 Area = 59.06 sq.m. ( GL.1-5/B-C & GL.33-37/B-C ) | E32: 449323.24 | F32: =E32 -> 449323.24 | G32: P | H32: =SUM(J32:CZ32) -> 1 | I32: =H32*F32 -> 449323.24 | AA32: 0.1 | AB32: 0.35 | AC32: 0.3 | AD32: 0.25
B33: =B32 -> 1.2.7 | D33: =D32 -> งานโครงสร้างต่อเติมพื้นชั้น 2 Area = 59.06 sq.m. ( GL.1-5/B-C & GL.33-37/B-C ) | F33: =E32 -> 449323.24 | G33: A | H33: =SUM(J33:CZ33) -> 0 | I33: =H33*F33 -> 0
A34: 1.2.8 | B34: =A34 -> 1.2.8 | C34: งานโครงสร้าง Platform สำหรับงานระบบ ( GL.23-37 / A ) | D34: =C34 -> งานโครงสร้าง Platform สำหรับงานระบบ ( GL.23-37 / A ) | E34: 91097.831 | F34: =E34 -> 91097.831 | G34: P | H34: =SUM(J34:CZ34) -> 1 | I34: =H34*F34 -> 91097.831 | AB34: 0.5 | AC34: 0.5
B35: =B34 -> 1.2.8 | D35: =D34 -> งานโครงสร้าง Platform สำหรับงานระบบ ( GL.23-37 / A ) | F35: =E34 -> 91097.831 | G35: A | H35: =SUM(J35:CZ35) -> 0 | I35: =H35*F35 -> 0
A36: 1.2.9 | B36: =A36 -> 1.2.9 | C36: งานโครงสร้างถังบำบัดน้ำเสีย ( GL.23-28 / A ) | D36: =C36 -> งานโครงสร้างถังบำบัดน้ำเสีย ( GL.23-28 / A ) | E36: 213666.43 | F36: =E36 -> 213666.43 | G36: P | H36: =SUM(J36:CZ36) -> 1 | I36: =H36*F36 -> 213666.43 | X36: 0.1 | Y36: 0.1 | Z36: 0.2 | AA36: 0.4 | AB36: 0.2
B37: =B36 -> 1.2.9 | D37: =D36 -> งานโครงสร้างถังบำบัดน้ำเสีย ( GL.23-28 / A ) | F37: =E36 -> 213666.43 | G37: A | H37: =SUM(J37:CZ37) -> 0 | I37: =H37*F37 -> 0
A38: 1.2.10 | B38: =A38 -> 1.2.10 | C38: งานโครงสร้างถังดักไขมัน ( GL.19-21 / A ) | D38: =C38 -> งานโครงสร้างถังดักไขมัน ( GL.19-21 / A ) | E38: 59959.248 | F38: =E38 -> 59959.248 | G38: P | H38: =SUM(J38:CZ38) -> 1 | I38: =H38*F38 -> 59959.248 | AC38: 0.25 | AD38: 0.4 | AE38: 0.35
B39: =B38 -> 1.2.10 | D39: =D38 -> งานโครงสร้างถังดักไขมัน ( GL.19-21 / A ) | F39: =E38 -> 59959.248 | G39: A | H39: =SUM(J39:CZ39) -> 0 | I39: =H39*F39 -> 0
A40: 1.2.11 | B40: =A40 -> 1.2.11 | C40: งานโครงสร้างฐานรากถังเก็บน้ำประปา ( GL.30-32 / A - B ) | D40: =C40 -> งานโครงสร้างฐานรากถังเก็บน้ำประปา ( GL.30-32 / A - B ) | E40: 126322.71 | F40: =E40 -> 126322.71 | G40: P | H40: =SUM(J40:CZ40) -> 1 | I40: =H40*F40 -> 126322.71 | AC40: 0.3 | AD40: 0.5 | AE40: 0.2
B41: =B40 -> 1.2.11 | D41: =D40 -> งานโครงสร้างฐานรากถังเก็บน้ำประปา ( GL.30-32 / A - B ) | F41: =E40 -> 126322.71 | G41: A | H41: =SUM(J41:CZ41) -> 0 | I41: =H41*F41 -> 0
A42: 1.2.12 | B42: =A42 -> 1.2.12 | C42: งานโครงสร้างบันได ST6 ชั้น1 to 1M ( GL.5-6 / C-B ) | D42: =C42 -> งานโครงสร้างบันได ST6 ชั้น1 to 1M ( GL.5-6 / C-B ) | E42: 51374.755 | F42: =E42 -> 51374.755 | G42: P | H42: =SUM(J42:CZ42) -> 1 | I42: =H42*F42 -> 51374.755 | X42: 0.25 | Y42: 0.5 | Z42: 0.25
...

Sheet progress
A1: project_start | B1: project_finish | C1: week_start | D1: plan | E1: actual
A2: 46082 | B2: 46630 | C2: ='NKC2'!J11 -> 46059 | D2: =INDEX('NKC2'!$J$129:$CM$129,1,ROW(A1))*100 -> 0 | E2: =INDEX('NKC2'!$J$138:$CM$138,1,ROW(A1))*100 -> 0
A3: =A2 -> 46082 | B3: =B2 -> 46630 | C3: =C2+7 -> 46066 | D3: =INDEX('NKC2'!$J$129:$CM$129,1,ROW(A2))*100 -> 0 | E3: =INDEX('NKC2'!$J$138:$CM$138,1,ROW(A2))*100 -> 0
A4: =A3 -> 46082 | B4: =B3 -> 46630 | C4: =C3+7 -> 46073 | D4: =INDEX('NKC2'!$J$129:$CM$129,1,ROW(A3))*100 -> 0 | E4: =INDEX('NKC2'!$J$138:$CM$138,1,ROW(A3))*100 -> 0
A5: =A4 -> 46082 | B5: =B4 -> 46630 | C5: =C4+7 -> 46080 | D5: =INDEX('NKC2'!$J$129:$CM$129,1,ROW(A4))*100 -> 0 | E5: =INDEX('NKC2'!$J$138:$CM$138,1,ROW(A4))*100 -> 0
A6: =A5 -> 46082 | B6: =B5 -> 46630 | C6: =C5+7 -> 46087 | D6: =INDEX('NKC2'!$J$129:$CM$129,1,ROW(A5))*100 -> 0.012678717 | E6: =INDEX('NKC2'!$J$138:$CM$138,1,ROW(A5))*100 -> 0
A7: =A6 -> 46082 | B7: =B6 -> 46630 | C7: =C6+7 -> 46094 | D7: =INDEX('NKC2'!$J$129:$CM$129,1,ROW(A6))*100 -> 0.03042892 | E7: =INDEX('NKC2'!$J$138:$CM$138,1,ROW(A6))*100 -> 0
A8: =A7 -> 46082 | B8: =B7 -> 46630 | C8: =C7+7 -> 46101 | D8: =INDEX('NKC2'!$J$129:$CM$129,1,ROW(A7))*100 -> 0.048179123 | E8: =INDEX('NKC2'!$J$138:$CM$138,1,ROW(A7))*100 -> 0
A9: =A8 -> 46082 | B9: =B8 -> 46630 | C9: =C8+7 -> 46108 | D9: =INDEX('NKC2'!$J$129:$CM$129,1,ROW(A8))*100 -> 0.068465069 | E9: =INDEX('NKC2'!$J$138:$CM$138,1,ROW(A8))*100 -> 0
A10: =A9 -> 46082 | B10: =B9 -> 46630 | C10: =C9+7 -> 46115 | D10: =INDEX('NKC2'!$J$129:$CM$129,1,ROW(A9))*100 -> 0.40547086 | E10: =INDEX('NKC2'!$J$138:$CM$138,1,ROW(A9))*100 -> 0.0050714866
A11: =A10 -> 46082 | B11: =B10 -> 46630 | C11: =C10+7 -> 46122 | D11: =INDEX('NKC2'!$J$129:$CM$129,1,ROW(A10))*100 -> 1.0691189 | E11: =INDEX('NKC2'!$J$138:$CM$138,1,ROW(A10))*100 -> 0.017750203
A12: =A11 -> 46082 | B12: =B11 -> 46630 | C12: =C11+7 -> 46129 | D12: =INDEX('NKC2'!$J$129:$CM$129,1,ROW(A11))*100 -> 1.8789256 | E12: =INDEX('NKC2'!$J$138:$CM$138,1,ROW(A11))*100 -> 0.03042892
A13: =A12 -> 46082 | B13: =B12 -> 46630 | C13: =C12+7 -> 46136 | D13: =INDEX('NKC2'!$J$129:$CM$129,1,ROW(A12))*100 -> 2.7068835 | E13: =INDEX('NKC2'!$J$138:$CM$138,1,ROW(A12))*100 -> 0.050714866
A14: =A13 -> 46082 | B14: =B13 -> 46630 | C14: =C13+7 -> 46143 | D14: =INDEX('NKC2'!$J$129:$CM$129,1,ROW(A13))*100 -> 3.6208692 | E14: =INDEX('NKC2'!$J$138:$CM$138,1,ROW(A13))*100 -> 0.071000813
... A80: =A79 -> 46082 | B80: =B79 -> 46630 | C80: =C79+7 -> 46605 | D80: =INDEX('NKC2'!$J$129:$CM$129,1,ROW(A79))*100 -> 100 | E80: =INDEX('NKC2'!$J$138:$CM$138,1,ROW(A79))*100 -> 0

Sheet progress_table
A1: WBS | B1: Activities | C1: Amount | D1: P/A | E1: %Progress | F1: ='NKC2'!J11 -> 46059 | G1: ='NKC2'!K11 -> 46066 | H1: ='NKC2'!L11 -> 46073 | I1: ='NKC2'!M11 -> 46080 | J1: ='NKC2'!N11 -> 46087 | K1: ='NKC2'!O11 -> 46094 | L1: ='NKC2'!P11 -> 46101 | M1: ='NKC2'!Q11 -> 46108 | ... CI1: ='NKC2'!CM11 -> 46626
A2: ='NKC2'!B14 -> 1 | B2: ='NKC2'!D14 -> งานก่อสร้างอาคาร Ratchadamnoen Center 2 | C2: ='NKC2'!F14 -> 1.4128269e+08 | D2: ='NKC2'!G12 -> P | E2: ='NKC2'!H14*100 -> 0 | F2: ='NKC2'!J14*100 -> 0 | G2: ='NKC2'!K14*100 -> 0 | H2: ='NKC2'!L14*100 -> 0 | I2: ='NKC2'!M14*100 -> 0 | J2: ='NKC2'!N14*100 -> 0 | K2: ='NKC2'!O14*100 -> 0 | L2: ='NKC2'!P14*100 -> 0 | M2: ='NKC2'!Q14*100 -> 0 | ... CI2: ='NKC2'!CM14*100 -> 0
A3: ='NKC2'!B15 -> 1 | B3: ='NKC2'!D15 -> งานก่อสร้างอาคาร Ratchadamnoen Center 2 | C3: ='NKC2'!F15 -> 1.4128269e+08 | D3: ='NKC2'!G13 -> A | E3: ='NKC2'!H15*100 -> 0 | F3: ='NKC2'!J15*100 -> 0 | G3: ='NKC2'!K15*100 -> 0 | H3: ='NKC2'!L15*100 -> 0 | I3: ='NKC2'!M15*100 -> 0 | J3: ='NKC2'!N15*100 -> 0 | K3: ='NKC2'!O15*100 -> 0 | L3: ='NKC2'!P15*100 -> 0 | M3: ='NKC2'!Q15*100 -> 0 | ... CI3: ='NKC2'!CM15*100 -> 0
A4: ='NKC2'!B16 -> 1.1 | B4: ='NKC2'!D16 -> งานรื้อถอนโครงสร้างและสถาปัตยกรรมอาคารเดิม | C4: ='NKC2'!F16 -> 358256.64 | D4: ='NKC2'!G14 -> P | E4: ='NKC2'!H16*100 -> 100 | F4: ='NKC2'!J16*100 -> 0 | G4: ='NKC2'!K16*100 -> 0 | H4: ='NKC2'!L16*100 -> 0 | I4: ='NKC2'!M16*100 -> 0 | J4: ='NKC2'!N16*100 -> 5 | K4: ='NKC2'!O16*100 -> 7 | L4: ='NKC2'!P16*100 -> 7 | M4: ='NKC2'!Q16*100 -> 8 | ... CI4: ='NKC2'!CM16*100 -> 0
A5: ='NKC2'!B17 -> 1.1 | B5: ='NKC2'!D17 -> งานรื้อถอนโครงสร้างและสถาปัตยกรรมอาคารเดิม | C5: ='NKC2'!F17 -> 358256.64 | D5: ='NKC2'!G15 -> A | E5: ='NKC2'!H17*100 -> 76 | F5: ='NKC2'!J17*100 -> 0 | G5: ='NKC2'!K17*100 -> 0 | H5: ='NKC2'!L17*100 -> 0 | I5: ='NKC2'!M17*100 -> 0 | J5: ='NKC2'!N17*100 -> 0 | K5: ='NKC2'!O17*100 -> 0 | L5: ='NKC2'!P17*100 -> 0 | M5: ='NKC2'!Q17*100 -> 0 | ... CI5: ='NKC2'!CM17*100 -> 0
A6: ='NKC2'!B18 -> 1.2 | B6: ='NKC2'!D18 -> งานโครงสร้าง | C6: ='NKC2'!F18 -> 15467541 | D6: ='NKC2'!G16 -> P | E6: ='NKC2'!H18*100 -> 0 | F6: ='NKC2'!J18*100 -> 0 | G6: ='NKC2'!K18*100 -> 0 | H6: ='NKC2'!L18*100 -> 0 | I6: ='NKC2'!M18*100 -> 0 | J6: ='NKC2'!N18*100 -> 0 | K6: ='NKC2'!O18*100 -> 0 | L6: ='NKC2'!P18*100 -> 0 | M6: ='NKC2'!Q18*100 -> 0 | ... CI6: ='NKC2'!CM18*100 -> 0
A7: ='NKC2'!B19 -> 1.2 | B7: ='NKC2'!D19 -> งานโครงสร้าง | C7: ='NKC2'!F19 -> 15467541 | D7: ='NKC2'!G17 -> A | E7: ='NKC2'!H19*100 -> 0 | F7: ='NKC2'!J19*100 -> 0 | G7: ='NKC2'!K19*100 -> 0 | H7: ='NKC2'!L19*100 -> 0 | I7: ='NKC2'!M19*100 -> 0 | J7: ='NKC2'!N19*100 -> 0 | K7: ='NKC2'!O19*100 -> 0 | L7: ='NKC2'!P19*100 -> 0 | M7: ='NKC2'!Q19*100 -> 0 | ... CI7: ='NKC2'!CM19*100 -> 0
A8: ='NKC2'!B20 -> 1.2.1 | B8: ='NKC2'!D20 -> งานโครงสร้างลิฟต์ | C8: ='NKC2'!F20 -> 1038486.6 | D8: ='NKC2'!G18 -> P | E8: ='NKC2'!H20*100 -> 100 | F8: ='NKC2'!J20*100 -> 0 | G8: ='NKC2'!K20*100 -> 0 | H8: ='NKC2'!L20*100 -> 0 | I8: ='NKC2'!M20*100 -> 0 | J8: ='NKC2'!N20*100 -> 0 | K8: ='NKC2'!O20*100 -> 0 | L8: ='NKC2'!P20*100 -> 0 | M8: ='NKC2'!Q20*100 -> 0 | ... CI8: ='NKC2'!CM20*100 -> 0
A9: ='NKC2'!B21 -> 1.2.1 | B9: ='NKC2'!D21 -> งานโครงสร้างลิฟต์ | C9: ='NKC2'!F21 -> 1038486.6 | D9: ='NKC2'!G19 -> A | E9: ='NKC2'!H21*100 -> 0 | F9: ='NKC2'!J21*100 -> 0 | G9: ='NKC2'!K21*100 -> 0 | H9: ='NKC2'!L21*100 -> 0 | I9: ='NKC2'!M21*100 -> 0 | J9: ='NKC2'!N21*100 -> 0 | K9: ='NKC2'!O21*100 -> 0 | L9: ='NKC2'!P21*100 -> 0 | M9: ='NKC2'!Q21*100 -> 0 | ... CI9: ='NKC2'!CM21*100 -> 0
A10: ='NKC2'!B22 -> 1.2.2 | B10: ='NKC2'!D22 -> งานโครงชั้นหลังคา (FL. +18.95 m. ) | C10: ='NKC2'!F22 -> 4195354.6 | D10: ='NKC2'!G20 -> P | E10: ='NKC2'!H22*100 -> 100 | F10: ='NKC2'!J22*100 -> 0 | G10: ='NKC2'!K22*100 -> 0 | H10: ='NKC2'!L22*100 -> 0 | I10: ='NKC2'!M22*100 -> 0 | J10: ='NKC2'!N22*100 -> 0 | K10: ='NKC2'!O22*100 -> 0 | L10: ='NKC2'!P22*100 -> 0 | M10: ='NKC2'!Q22*100 -> 0 | ... CI10: ='NKC2'!CM22*100 -> 0
A11: ='NKC2'!B23 -> 1.2.2 | B11: ='NKC2'!D23 -> งานโครงชั้นหลังคา (FL. +18.95 m. ) | C11: ='NKC2'!F23 -> 4195354.6 | D11: ='NKC2'!G21 -> A | E11: ='NKC2'!H23*100 -> 0 | F11: ='NKC2'!J23*100 -> 0 | G11: ='NKC2'!K23*100 -> 0 | H11: ='NKC2'!L23*100 -> 0 | I11: ='NKC2'!M23*100 -> 0 | J11: ='NKC2'!N23*100 -> 0 | K11: ='NKC2'!O23*100 -> 0 | L11: ='NKC2'!P23*100 -> 0 | M11: ='NKC2'!Q23*100 -> 0 | ... CI11: ='NKC2'!CM23*100 -> 0
A12: ='NKC2'!B24 -> 1.2.3 | B12: ='NKC2'!D24 -> งานโครงหลังคาห้องสนามหลวง ห้องศาสนา | C12: ='NKC2'!F24 -> 1034941.9 | D12: ='NKC2'!G22 -> P | E12: ='NKC2'!H24*100 -> 100 | F12: ='NKC2'!J24*100 -> 0 | G12: ='NKC2'!K24*100 -> 0 | H12: ='NKC2'!L24*100 -> 0 | I12: ='NKC2'!M24*100 -> 0 | J12: ='NKC2'!N24*100 -> 0 | K12: ='NKC2'!O24*100 -> 0 | L12: ='NKC2'!P24*100 -> 0 | M12: ='NKC2'!Q24*100 -> 0 | ... CI12: ='NKC2'!CM24*100 -> 0
A13: ='NKC2'!B25 -> 1.2.3 | B13: ='NKC2'!D25 -> งานโครงหลังคาห้องสนามหลวง ห้องศาสนา | C13: ='NKC2'!F25 -> 1034941.9 | D13: ='NKC2'!G23 -> A | E13: ='NKC2'!H25*100 -> 0 | F13: ='NKC2'!J25*100 -> 0 | G13: ='NKC2'!K25*100 -> 0 | H13: ='NKC2'!L25*100 -> 0 | I13: ='NKC2'!M25*100 -> 0 | J13: ='NKC2'!N25*100 -> 0 | K13: ='NKC2'!O25*100 -> 0 | L13: ='NKC2'!P25*100 -> 0 | M13: ='NKC2'!Q25*100 -> 0 | ... CI13: ='NKC2'!CM25*100 -> 0
... A39: ='NKC2'!B51 -> 1.3.1 | B39: ='NKC2'!D51 -> งานก่อช่อง ชาฟ | C39: ='NKC2'!F51 -> 20066.118 | D39: ='NKC2'!G49 -> A | E39: ='NKC2'!H51*100 -> 0 | F39: ='NKC2'!J51*100 -> 0 | G39: ='NKC2'!K51*100 -> 0 | H39: ='NKC2'!L51*100 -> 0 | I39: ='NKC2'!M51*100 -> 0 | J39: ='NKC2'!N51*100 -> 0 | K39: ='NKC2'!O51*100 -> 0 | L39: ='NKC2'!P51*100 -> 0 | M39: ='NKC2'!Q51*100 -> 0 | ... CI39: ='NKC2'!CM51*100 -> 0
A40: ='NKC2'!B54 -> 1.3.3 | B40: ='NKC2'!D54 -> Sanitary and Fire Protection Riser | C40: ='NKC2'!F54 -> 252597.19 | D40: ='NKC2'!G50 -> P | E40: ='NKC2'!H54*100 -> 100 | F40: ='NKC2'!J54*100 -> 0 | G40: ='NKC2'!K54*100 -> 0 | H40: ='NKC2'!L54*100 -> 0 | I40: ='NKC2'!M54*100 -> 0 | J40: ='NKC2'!N54*100 -> 0 | K40: ='NKC2'!O54*100 -> 0 | L40: ='NKC2'!P54*100 -> 0 | M40: ='NKC2'!Q54*100 -> 0 | ... CI40: ='NKC2'!CM54*100 -> 0
A41: ='NKC2'!B55 -> 1.3.3 | B41: ='NKC2'!D55 -> Sanitary and Fire Protection Riser | C41: ='NKC2'!F55 -> 252597.19 | D41: ='NKC2'!G51 -> A | E41: ='NKC2'!H55*100 -> 0 | F41: ='NKC2'!J55*100 -> 0 | G41: ='NKC2'!K55*100 -> 0 | H41: ='NKC2'!L55*100 -> 0 | I41: ='NKC2'!M55*100 -> 0 | J41: ='NKC2'!N55*100 -> 0 | K41: ='NKC2'!O55*100 -> 0 | L41: ='NKC2'!P55*100 -> 0 | M41: ='NKC2'!Q55*100 -> 0 | ... CI41: ='NKC2'!CM55*100 -> 0
A42: ='NKC2'!B56 -> 1.3.4 | B42: ='NKC2'!D56 -> Air Conditioning Riser | C42: ='NKC2'!F56 -> 56860.24 | D42: ='NKC2'!G54 -> P | E42: ='NKC2'!H56*100 -> 100 | F42: ='NKC2'!J56*100 -> 0 | G42: ='NKC2'!K56*100 -> 0 | H42: ='NKC2'!L56*100 -> 0 | I42: ='NKC2'!M56*100 -> 0 | J42: ='NKC2'!N56*100 -> 0 | K42: ='NKC2'!O56*100 -> 0 | L42: ='NKC2'!P56*100 -> 0 | M42: ='NKC2'!Q56*100 -> 0 | ... CI42: ='NKC2'!CM56*100 -> 0
A43: ='NKC2'!B57 -> 1.3.4 | B43: ='NKC2'!D57 -> Air Conditioning Riser | C43: ='NKC2'!F57 -> 56860.24 | D43: ='NKC2'!G55 -> A | E43: ='NKC2'!H57*100 -> 0 | F43: ='NKC2'!J57*100 -> 0 | G43: ='NKC2'!K57*100 -> 0 | H43: ='NKC2'!L57*100 -> 0 | I43: ='NKC2'!M57*100 -> 0 | J43: ='NKC2'!N57*100 -> 0 | K43: ='NKC2'!O57*100 -> 0 | L43: ='NKC2'!P57*100 -> 0 | M43: ='NKC2'!Q57*100 -> 0 | ... CI43: ='NKC2'!CM57*100 -> 0
A44: ='NKC2'!B58 -> 1.4 | B44: ='NKC2'!D58 -> งานสถาปัตยกรรมและงานระบบประกอบอาคาร | C44: ='NKC2'!F58 -> 82272490 | D44: ='NKC2'!G56 -> P | E44: ='NKC2'!H58*100 -> 0 | F44: ='NKC2'!J58*100 -> 0 | G44: ='NKC2'!K58*100 -> 0 | H44: ='NKC2'!L58*100 -> 0 | I44: ='NKC2'!M58*100 -> 0 | J44: ='NKC2'!N58*100 -> 0 | K44: ='NKC2'!O58*100 -> 0 | L44: ='NKC2'!P58*100 -> 0 | M44: ='NKC2'!Q58*100 -> 0 | ... CI44: ='NKC2'!CM58*100 -> 0
A45: ='NKC2'!B59 -> 1.4 | B45: ='NKC2'!D59 -> งานสถาปัตยกรรมและงานระบบประกอบอาคาร | C45: ='NKC2'!F59 -> 82272490 | D45: ='NKC2'!G57 -> A | E45: ='NKC2'!H59*100 -> 0 | F45: ='NKC2'!J59*100 -> 0 | G45: ='NKC2'!K59*100 -> 0 | H45: ='NKC2'!L59*100 -> 0 | I45: ='NKC2'!M59*100 -> 0 | J45: ='NKC2'!N59*100 -> 0 | K45: ='NKC2'!O59*100 -> 0 | L45: ='NKC2'!P59*100 -> 0 | M45: ='NKC2'!Q59*100 -> 0 | ... CI45: ='NKC2'!CM59*100 -> 0
A46: ='NKC2'!B60 -> 1.4.1 | B46: ='NKC2'!D60 -> งานสถาปัตยกรรมและ MEP ภายในอาคาร | C46: ='NKC2'!F60 -> 69821580 | D46: ='NKC2'!G58 -> P | E46: ='NKC2'!H60*100 -> 0 | F46: ='NKC2'!J60*100 -> 0 | G46: ='NKC2'!K60*100 -> 0 | H46: ='NKC2'!L60*100 -> 0 | I46: ='NKC2'!M60*100 -> 0 | J46: ='NKC2'!N60*100 -> 0 | K46: ='NKC2'!O60*100 -> 0 | L46: ='NKC2'!P60*100 -> 0 | M46: ='NKC2'!Q60*100 -> 0 | ... CI46: ='NKC2'!CM60*100 -> 0
A47: ='NKC2'!B61 -> 1.4.1 | B47: ='NKC2'!D61 -> งานสถาปัตยกรรมและ MEP ภายในอาคาร | C47: ='NKC2'!F61 -> 69821580 | D47: ='NKC2'!G59 -> A | E47: ='NKC2'!H61*100 -> 0 | F47: ='NKC2'!J61*100 -> 0 | G47: ='NKC2'!K61*100 -> 0 | H47: ='NKC2'!L61*100 -> 0 | I47: ='NKC2'!M61*100 -> 0 | J47: ='NKC2'!N61*100 -> 0 | K47: ='NKC2'!O61*100 -> 0 | L47: ='NKC2'!P61*100 -> 0 | M47: ='NKC2'!Q61*100 -> 0 | ... CI47: ='NKC2'!CM61*100 -> 0
A48: ='NKC2'!B62 -> 1.4.1.1 | B48: ='NKC2'!D62 -> Roof | C48: ='NKC2'!F62 -> 7011934.2 | D48: ='NKC2'!G60 -> P | E48: ='NKC2'!H62*100 -> 100 | F48: ='NKC2'!J62*100 -> 0 | G48: ='NKC2'!K62*100 -> 0 | H48: ='NKC2'!L62*100 -> 0 | I48: ='NKC2'!M62*100 -> 0 | J48: ='NKC2'!N62*100 -> 0 | K48: ='NKC2'!O62*100 -> 0 | L48: ='NKC2'!P62*100 -> 0 | M48: ='NKC2'!Q62*100 -> 0 | ... CI48: ='NKC2'!CM62*100 -> 0
A49: ='NKC2'!B63 -> 1.4.1.1 | B49: ='NKC2'!D63 -> Roof | C49: ='NKC2'!F63 -> 7011934.2 | D49: ='NKC2'!G61 -> A | E49: ='NKC2'!H63*100 -> 0 | F49: ='NKC2'!J63*100 -> 0 | G49: ='NKC2'!K63*100 -> 0 | H49: ='NKC2'!L63*100 -> 0 | I49: ='NKC2'!M63*100 -> 0 | J49: ='NKC2'!N63*100 -> 0 | K49: ='NKC2'!O63*100 -> 0 | L49: ='NKC2'!P63*100 -> 0 | M49: ='NKC2'!Q63*100 -> 0 | ... CI49: ='NKC2'!CM63*100 -> 0
A50: ='NKC2'!B64 -> 1.4.1.2 | B50: ='NKC2'!D64 -> 3rd Floor | C50: ='NKC2'!F64 -> 18765199 | D50: ='NKC2'!G62 -> P | E50: ='NKC2'!H64*100 -> 100 | F50: ='NKC2'!J64*100 -> 0 | G50: ='NKC2'!K64*100 -> 0 | H50: ='NKC2'!L64*100 -> 0 | I50: ='NKC2'!M64*100 -> 0 | J50: ='NKC2'!N64*100 -> 0 | K50: ='NKC2'!O64*100 -> 0 | L50: ='NKC2'!P64*100 -> 0 | M50: ='NKC2'!Q64*100 -> 0 | ... CI50: ='NKC2'!CM64*100 -> 0
A51: ='NKC2'!B65 -> 1.4.1.2 | B51: ='NKC2'!D65 -> 3rd Floor | C51: ='NKC2'!F65 -> 18765199 | D51: ='NKC2'!G63 -> A | E51: ='NKC2'!H65*100 -> 0 | F51: ='NKC2'!J65*100 -> 0 | G51: ='NKC2'!K65*100 -> 0 | H51: ='NKC2'!L65*100 -> 0 | I51: ='NKC2'!M65*100 -> 0 | J51: ='NKC2'!N65*100 -> 0 | K51: ='NKC2'!O65*100 -> 0 | L51: ='NKC2'!P65*100 -> 0 | M51: ='NKC2'!Q65*100 -> 0 | ... CI51: ='NKC2'!CM65*100 -> 0
A52: ='NKC2'!B66 -> 1.4.1.3 | B52: ='NKC2'!D66 -> 2nd Floor | C52: ='NKC2'!F66 -> 17875973 | D52: ='NKC2'!G64 -> P | E52: ='NKC2'!H66*100 -> 100 | F52: ='NKC2'!J66*100 -> 0 | G52: ='NKC2'!K66*100 -> 0 | H52: ='NKC2'!L66*100 -> 0 | I52: ='NKC2'!M66*100 -> 0 | J52: ='NKC2'!N66*100 -> 0 | K52: ='NKC2'!O66*100 -> 0 | L52: ='NKC2'!P66*100 -> 0 | M52: ='NKC2'!Q66*100 -> 0 | ... CI52: ='NKC2'!CM66*100 -> 0
A53: ='NKC2'!B67 -> 1.4.1.3 | B53: ='NKC2'!D67 -> 2nd Floor | C53: ='NKC2'!F67 -> 17875973 | D53: ='NKC2'!G65 -> A | E53: ='NKC2'!H67*100 -> 0 | F53: ='NKC2'!J67*100 -> 0 | G53: ='NKC2'!K67*100 -> 0 | H53: ='NKC2'!L67*100 -> 0 | I53: ='NKC2'!M67*100 -> 0 | J53: ='NKC2'!N67*100 -> 0 | K53: ='NKC2'!O67*100 -> 0 | L53: ='NKC2'!P67*100 -> 0 | M53: ='NKC2'!Q67*100 -> 0 | ... CI53: ='NKC2'!CM67*100 -> 0
... A111: ='NKC2'!B125 -> 1.8.6 | B111: ='NKC2'!D125 -> งานครุภัณฑ์ Soft Scape | C111: ='NKC2'!F125 -> 760477.35 | D111: ='NKC2'!G123 -> A | E111: ='NKC2'!H125*100 -> 0 | F111: ='NKC2'!J125*100 -> 0 | G111: ='NKC2'!K125*100 -> 0 | H111: ='NKC2'!L125*100 -> 0 | I111: ='NKC2'!M125*100 -> 0 | J111: ='NKC2'!N125*100 -> 0 | K111: ='NKC2'!O125*100 -> 0 | L111: ='NKC2'!P125*100 -> 0 | M111: ='NKC2'!Q125*100 -> 0 | ... CI111: ='NKC2'!CM125*100 -> 0
